# 🚨 דוח תיקון שגיאת "object dict can't be used in 'await' expression"

## סיכום הבעיה
הבוט נכשל עם שגיאה קריטית:
```
🚨 שגיאה קריטית בבוט:
object dict can't be used in 'await' expression
משתמש: 111709341
הודעה: על מה מדובר
```

## גורם השגיאה
השגיאה נגרמה בגלל ערבוב בין פונקציות סינכרוניות ואסינכרוניות בקוד ה-background processors:

1. **הבעיה הראשית**: בקובץ `message_handler.py`, הפונקציה `run_background_processors` הוסיפה פונקציות סינכרוניות לרשימת tasks שאמורה להכיל רק coroutines עבור `asyncio.gather()`.

2. **פונקציות בעייתיות**:
   - `smart_update_profile_with_gpt_d` - פונקציה סינכרונית שמחזירה tuple
   - `extract_user_info` - פונקציה סינכרונית שמחזירה dictionary

## התיקונים שבוצעו

### 1. תיקון GPT-D Handler ב-`message_handler.py`

**לפני:**
```python
# GPT-D - עדכון חכם של פרופיל
tasks.append(smart_update_profile_with_gpt_d(chat_id, user_msg, bot_reply))
```

**אחרי:**
```python
# GPT-D - עדכון חכם של פרופיל
tasks.append(smart_update_profile_with_gpt_d_async(chat_id, user_msg, bot_reply))
```

**שינויים נוספים:**
- הוספת import של `smart_update_profile_with_gpt_d_async`
- השתמשתי בגרסה האסינכרונית הקיימת של הפונקציה

### 2. תיקון GPT-C Handler ב-`message_handler.py`

**לפני:**
```python
# GPT-C - עדכון פרופיל משתמש
if should_run_gpt_c(user_msg):
    tasks.append(extract_user_info(chat_id, user_msg))
```

**אחרי:**
```python
# GPT-C - עדכון פרופיל משתמש (sync function, run separately)
gpt_c_task = None
if should_run_gpt_c(user_msg):
    gpt_c_task = asyncio.create_task(asyncio.to_thread(extract_user_info, user_msg, chat_id))
```

### 3. תיקון אסיפת המשימות

**לפני:**
```python
# הפעלה במקביל של כל התהליכים
if tasks:
    await asyncio.gather(*tasks, return_exceptions=True)
```

**אחרי:**
```python
# הפעלה במקביל של כל התהליכים
all_tasks = []
if gpt_c_task:
    all_tasks.append(gpt_c_task)
all_tasks.extend(tasks)

if all_tasks:
    await asyncio.gather(*all_tasks, return_exceptions=True)
```

### 4. ניקוי קוד בעייתי

הסרתי קוד שגוי מהפונקציה `handle_unregistered_user_background` שהכיל משתנים לא קיימים שהיו גורמים לשגיאות נוספות.

## אימות התיקונים

✅ **בדיקת תחביר**: שני הקבצים שתוקנו עוברים בדיקת תחביר Python:
- `message_handler.py` - ✅ תקין
- `gpt_d_handler.py` - ✅ תקין

## התוצאה הצפויה

לאחר התיקונים:
1. הבוט לא יתנפח יותר על השגיאה "object dict can't be used in 'await' expression"
2. כל ה-background processors (GPT-C, GPT-D, GPT-E) יכולים לרוץ במקביל ללא שגיאות
3. המשתמש 111709341 וכל משתמש אחר יוכלו לקבל תגובות תקינות
4. מערכת ההתאוששות תפעל כראוי עבור משתמשים שנפגעו מהשגיאה

## הערות טכניות

- השתמשתי ב-`asyncio.to_thread()` כדי להריץ את הפונקציה הסינכרונית `extract_user_info` בthread נפרד
- הגרסה האסינכרונית `smart_update_profile_with_gpt_d_async` כבר הייתה קיימת ומשתמשת ב-`loop.run_in_executor()`
- כל התיקונים שומרים על התנהגות המקורית של הקוד אבל עם async/await נכון

## זמן פתרון
התיקון בוצע ב-02/07/2025 ואמור לפתור מיידית את הבעיה בסביבת הייצור.